2015-09-24 17:30:13
Traceback (most recent call last):
  File "/Users/wbond/Library/Application Support/Sublime Text 3/Packages/SFTP/sftp/file_transfer.py", line 322, in handle_get_dirs
  File "/Users/wbond/Library/Application Support/Sublime Text 3/Packages/SFTP/sftp/sftp_transport.py", line 324, in lcd
SFTP.sftp.errors.NotFoundError: Folder not found

During handling of the above exception, another exception occurred:

Traceback (most recent call last):
  File "/Users/wbond/Library/Application Support/Sublime Text 3/Packages/SFTP/sftp/threads.py", line 15, in run_with_except_hook
  File "/Users/wbond/Library/Application Support/Sublime Text 3/Packages/SFTP/sftp/threads.py", line 113, in handler
  File "/Users/wbond/Library/Application Support/Sublime Text 3/Packages/SFTP/sftp/commands.py", line 332, in run
  File "/Users/wbond/Library/Application Support/Sublime Text 3/Packages/SFTP/sftp/commands.py", line 480, in do_operation
  File "/Users/wbond/Library/Application Support/Sublime Text 3/Packages/SFTP/sftp/file_transfer.py", line 34, in handler
  File "/Users/wbond/Library/Application Support/Sublime Text 3/Packages/SFTP/sftp/sftp_transport.py", line 354, in get
  File "/Users/wbond/Library/Application Support/Sublime Text 3/Packages/SFTP/sftp/file_transfer.py", line 328, in handle_get_dirs
  File "/Users/wbond/Library/Application Support/Sublime Text 3/Packages/SFTP/sftp/sftp_transport.py", line 324, in lcd
SFTP.sftp.errors.NotFoundError: Folder not found
